<?xml version="1.0" encoding="utf-8"?>
<!-- =================================================================================== -->
<!-- |    This document was autogenerated by xacro from digit_model.xacro              | -->
<!-- |    EDITING THIS FILE BY HAND IS NOT RECOMMENDED                                 | -->
<!-- =================================================================================== -->
<!-- Author: Guillermo Castillo
	 Email:  castillomartinez.2@osu.edu
     Date:   03/20/2020   -->
<robot name="digit_arm_fixed_right_pinned_simplified">
  <link name="right_toe_roll">
    <inertial>
      <origin rpy="0 0 0" xyz="9e-06 0.028084 -0.023204"/>
      <mass value="0.531283"/>
      <inertia ixx="0.00187" ixy="0" ixz="0" iyy="0.001616" iyz="-0.000566" izz="0.000843"/>
    </inertial>
    <visual>
      <origin rpy="0 0 0" xyz="0 0 0"/>
      <geometry>
        <mesh filename="package://digit_model/meshes/toe-roll.stl"/>
      </geometry>
      <material name="light_grey">
        <color rgba="0.75 0.75 0.75 1"/>
      </material>
    </visual>
  </link>
  <link name="right_toe_pitch">
    <inertial>
      <origin rpy="0 0 0" xyz="-3e-06 -2e-06 -0.000141"/>
      <mass value="0.043881"/>
      <inertia ixx="0.0000050" ixy="-0.0000000" ixz="0.0000000" iyy="0.0000080" iyz="-0.0000000" izz="0.0000050"/>
    </inertial>
    <visual>
      <origin rpy="0 0 0" xyz="0 0 0"/>
      <geometry>
        <mesh filename="package://digit_model/meshes/toe-pitch.stl"/>
      </geometry>
      <material name="light_grey">
        <color rgba="0.75 0.75 0.75 1"/>
      </material>
    </visual>
  </link>
  <link name="right_tarsus">
    <inertial>
      <origin rpy="0 0 0" xyz="-0.13910751970333218308 -0.38271450574474258355 0.000678"/>
      <mass value="1.322865"/>
      <inertia ixx="0.0139146" ixy="0.0057233" ixz="0.0000290" iyy="0.0034264" iyz="-0.0000982" izz="0.0165010"/>
    </inertial>
    <visual>
      <origin rpy="0 0 0" xyz="0 0 0"/>
      <geometry>
        <mesh filename="package://digit_model/meshes/tarsus.stl"/>
      </geometry>
      <material name="grey">
        <color rgba="0.35 0.35 0.35 1"/>
      </material>
    </visual>
  </link>
  <link name="right_knee">
    <inertial>
      <origin rpy="0 0 0" xyz="0.06498814247864816152 -0.36464161700512709441 0.001409"/>
      <mass value="2.12287"/>
      <inertia ixx="0.0430188" ixy="-0.0112872" ixz="-0.0001174" iyy="0.0070223" iyz="-0.0003008" izz="0.0484917"/>
    </inertial>
    <visual>
      <origin rpy="0 0 0" xyz="0 0 0"/>
      <geometry>
        <mesh filename="package://digit_model/meshes/knee.stl"/>
      </geometry>
      <material name="grey">
        <color rgba="0.35 0.35 0.35 1"/>
      </material>
    </visual>
  </link>
  <link name="right_hip_pitch">
    <inertial>
      <origin rpy="0 0 0" xyz="-0.000521 0.059463 -0.043357"/>
      <mass value="6.244279"/>
      <inertia ixx="0.0333450" ixy="-0.0001710" ixz="0.0001780" iyy="0.0115330" iyz="0.0001480" izz="0.0339580"/>
    </inertial>
    <visual>
      <origin rpy="0 0 0" xyz="0 0 0"/>
      <geometry>
        <mesh filename="package://digit_model/meshes/hip-pitch.stl"/>
      </geometry>
      <material name="scarlet">
        <color rgba="0.89 0.13 0.0 1"/>
      </material>
    </visual>
  </link>
  <link name="right_hip_yaw">
    <inertial>
      <origin rpy="0 0 0" xyz="-0.01836850717076765616 -0.01835436503952019363 0.005945"/>
      <mass value="0.818753"/>
      <inertia ixx="0.0017770" ixy="-0.0000389" ixz="0.0001510" iyy="0.0007700" iyz="-0.0000361" izz="0.0017790"/>
    </inertial>
    <visual>
      <origin rpy="0 0 0" xyz="0 0 0"/>
      <geometry>
        <mesh filename="package://digit_model/meshes/hip-pitch-housing.stl"/>
      </geometry>
      <material name="light_grey">
        <color rgba="0.75 0.75 0.75 1"/>
      </material>
    </visual>
  </link>
  <link name="right_hip_roll">
    <inertial>
      <origin rpy="0 0 0" xyz="-0.012565 -0.000244 -0.048533"/>
      <mass value="0.915088"/>
      <inertia ixx="0.0007660" ixy="-0.0000040" ixz="-0.0000130" iyy="0.0011480" iyz="0.0000030" izz="0.0010170"/>
    </inertial>
    <visual>
      <origin rpy="0 0 0" xyz="0 0 0"/>
      <geometry>
        <mesh filename="package://digit_model/meshes/hip-yaw-housing.stl"/>
      </geometry>
      <material name="grey">
        <color rgba="0.35 0.35 0.35 1"/>
      </material>
    </visual>
  </link>
  <link name="torso">
    <inertial>
      <origin rpy="0 0 0" xyz="0.31074618261439068689 -0.02664155968001136882 0.009505"/>
      <mass value="22.211836"/>
      <inertia ixx="0.2380243" ixy="-0.0386244" ixz="-0.0541286" iyy="0.5699658" iyz="0.0089270" izz="0.5721731"/>
    </inertial>
    <visual>
      <origin rpy="0 0 0" xyz="0 0 0"/>
      <geometry>
        <mesh filename="package://digit_model/meshes/torso.stl"/>
      </geometry>
      <material name="scarlet">
        <color rgba="0.89 0.13 0.0 1"/>
      </material>
    </visual>
  </link>
  <link name="left_hip_roll">
    <inertial>
      <origin rpy="0 0 0" xyz="-0.001967 0.000244 0.031435"/>
      <mass value="0.915088"/>
      <inertia ixx="0.001017" ixy="-3e-06" ixz="1.3e-05" iyy="0.001148" iyz="-4e-06" izz="0.000766"/>
    </inertial>
    <visual>
      <origin rpy="0 0 0" xyz="0 0 0"/>
      <geometry>
        <mesh filename="package://digit_model/meshes/hip-yaw-housing.stl"/>
      </geometry>
      <material name="grey">
        <color rgba="0.35 0.35 0.35 1"/>
      </material>
    </visual>
  </link>
  <link name="left_hip_yaw">
    <inertial>
      <origin rpy="0 0 0" xyz="1e-05 -0.001945 0.042033"/>
      <mass value="0.818753"/>
      <inertia ixx="0.001627" ixy="-1e-06" ixz="2e-06" iyy="0.001929" iyz="5.3e-05" izz="0.00077"/>
    </inertial>
    <visual>
      <origin rpy="0 0 0" xyz="0 0 0"/>
      <geometry>
        <mesh filename="package://digit_model/meshes/hip-pitch-housing.stl"/>
      </geometry>
      <material name="light_grey">
        <color rgba="0.75 0.75 0.75 1"/>
      </material>
    </visual>
  </link>
  <link name="left_hip_pitch">
    <inertial>
      <origin rpy="0 0 0" xyz="0.060537 0.000521 -0.038857"/>
      <mass value="6.244279"/>
      <inertia ixx="0.011533" ixy="-0.000171" ixz="0.000148" iyy="0.033345" iyz="0.000178" izz="0.033958"/>
    </inertial>
    <visual>
      <origin rpy="0 0 0" xyz="0 0 0"/>
      <geometry>
        <mesh filename="package://digit_model/meshes/hip-pitch.stl"/>
      </geometry>
      <material name="scarlet">
        <color rgba="0.89 0.13 0.0 1"/>
      </material>
    </visual>
  </link>
  <link name="left_knee">
    <inertial>
      <origin rpy="0 0 0" xyz="0.125521 0.048702 0.001409"/>
      <mass value="2.12287"/>
      <inertia ixx="0.0038958511830902179881586100407276" ixy="-0.0022549563447054757694965054781733" ixz="0.00031953698358845871200714650051111" iyy="0.0461452185010313292723438394205" iyz="0.00004671630564203102363050532086497" izz="0.048491712853366647495434449410823"/>
    </inertial>
    <visual>
      <origin rpy="0 0 0" xyz="0 0 0"/>
      <geometry>
        <mesh filename="package://digit_model/meshes/knee.stl"/>
      </geometry>
      <material name="grey">
        <color rgba="0.35 0.35 0.35 1"/>
      </material>
    </visual>
  </link>
  <link name="left_tarsus">
    <inertial>
      <origin rpy="0 0 0" xyz="0.000932 -0.029183 0.000678"/>
      <mass value="1.322865"/>
      <inertia ixx="0.000932" ixy="0.00061" ixz="0.000102" iyy="0.016409" iyz="9e-06" izz="0.016501"/>
    </inertial>
    <visual>
      <origin rpy="0 0 0" xyz="0 0 0"/>
      <geometry>
        <mesh filename="package://digit_model/meshes/tarsus.stl"/>
      </geometry>
      <material name="grey">
        <color rgba="0.35 0.35 0.35 1"/>
      </material>
    </visual>
  </link>
  <link name="left_toe_pitch">
    <inertial>
      <origin rpy="0 0 0" xyz="-0.000141 2e-06 3e-06"/>
      <mass value="0.043881"/>
      <inertia ixx="5e-06" ixy="0" ixz="0" iyy="8e-06" iyz="0" izz="5e-06"/>
    </inertial>
    <visual>
      <origin rpy="0 0 0" xyz="0 0 0"/>
      <geometry>
        <mesh filename="package://digit_model/meshes/toe-pitch.stl"/>
      </geometry>
      <material name="light_grey">
        <color rgba="0.75 0.75 0.75 1"/>
      </material>
    </visual>
  </link>
  <link name="left_toe_roll">
    <inertial>
      <origin rpy="0 0 0" xyz="9e-06 -0.028084 -0.023204"/>
      <mass value="0.531283"/>
      <inertia ixx="0.00187" ixy="0" ixz="0" iyy="0.001616" iyz="0.000566" izz="0.000843"/>
    </inertial>
    <visual>
      <origin rpy="0 0 0" xyz="0 0 0"/>
      <geometry>
        <mesh filename="package://digit_model/meshes/toe-roll.stl"/>
      </geometry>
      <material name="light_grey">
        <color rgba="0.75 0.75 0.75 1"/>
      </material>
    </visual>
  </link>
  <joint name="toe_roll_joint_right" type="continuous">
    <!--<origin rpy="0 1.57079632679 0" xyz="0 0 0"/>-->
    <origin rpy="0 0 0" xyz="0 0 0"/>
    <axis xyz="0 0 1"/>
    <parent link="right_toe_roll"/>
    <child link="right_toe_pitch"/>
    <limit effort="0.9" lower="-0.6109" upper="0.6109" velocity="11.5"/>
  </joint>
  <joint name="toe_pitch_joint_right" type="continuous">
    <origin rpy="0 -1.57079632679489655800 0 " xyz="0 0 0 "/>
    <axis xyz="0 0 1"/>
    <parent link="right_toe_pitch"/>
    <child link="right_tarsus"/>
    <limit effort="0.9" lower="-0.785398163397" upper="0.785398163397" velocity="11.5"/>
  </joint>
  <joint name="shin_to_tarsus_right" type="continuous">
    <origin rpy="0 0 1.19560030311935294733 " xyz="-0.11229615315891616767 -0.39427592353923257562 0"/>
    <axis xyz="0 0 1"/>
    <parent link="right_tarsus"/>
    <child link="right_knee"/>
    <limit effort="0" lower="-1.2497" upper="0.8779" velocity="20"/>
  </joint>
  <joint name="knee_joint_right" type="continuous">
    <origin rpy="0 0 1.79768909117662833985 " xyz="0.04577044631356060045 -0.49790109745919752804 0"/>
    <axis xyz="0 0 1"/>
    <parent link="right_knee"/>
    <child link="right_hip_pitch"/>
    <limit effort="12.5" lower="-0.8727" upper="1.2392" velocity="8.5085"/>
  </joint>
  <joint name="hip_flexion_right" type="continuous">
    <origin rpy="0 0 -1.57079632679489655800 " xyz="0 0.12 -0.0045"/>
    <axis xyz="0 0 -1"/>
    <parent link="right_hip_pitch"/>
    <child link="right_hip_yaw"/>
    <limit effort="12.5" lower="-1.57079632679" upper="1.0472" velocity="8.5"/>
  </joint>
  <joint name="hip_rotation_right" type="continuous">
    <origin rpy="1.57079632679489678004 0 2.35619449019234483700 " xyz="-0.04808324624137506886 -0.04808324624137506886 0.004"/>
    <axis xyz="0 0 1"/>
    <parent link="right_hip_yaw"/>
    <child link="right_hip_roll"/>
    <limit effort="1.4" lower="-0.698132" upper="0.698132" velocity="12.15"/>
  </joint>
  <joint name="hip_abduction_right" type="continuous">
    <origin rpy="0 1.57079632679489655800 0 " xyz="-0.044 0 -0.0505"/>
    <axis xyz="0 0 1"/>
    <parent link="right_hip_roll"/>
    <child link="torso"/>
    <limit effort="1.4" lower="-1.0472" upper="1.0472" velocity="12.15"/>
  </joint>
  <joint name="hip_abduction_left" type="continuous">
    <origin rpy="0 0 -0.7504911466904076178252580575645" xyz="0.06670313946174037667 0.16933596801021977285 0 "/>
    <axis xyz="0 0 1"/>
    <parent link="torso"/>
    <child link="left_hip_roll"/>
    <limit effort="1.4" lower="-1.0472" upper="1.0472" velocity="12.15"/>
  </joint>
  <joint name="hip_rotation_left" type="continuous">
    <origin rpy="0 -1.57079632679 0" xyz="-0.0505 0 0.044"/>
    <axis xyz="0 0 1"/>
    <parent link="left_hip_roll"/>
    <child link="left_hip_yaw"/>
    <limit effort="1.4" lower="-0.698132" upper="0.698132" velocity="12.15"/>
  </joint>
  <joint name="hip_flexion_left" type="continuous">
    <origin rpy="-1.57079632679 -0.785398163397 3.14159265359" xyz="0 0.004 0.068"/>
    <axis xyz="0 0 -1"/>
    <parent link="left_hip_yaw"/>
    <child link="left_hip_pitch"/>
    <limit effort="12.5" lower="-1.0472" upper="1.57079632679" velocity="8.5"/>
  </joint>
  <joint name="knee_joint_left" type="continuous">
    <origin rpy="0 0 -1.57079632679" xyz="0.12 0 0.0045"/>
    <axis xyz="0 0 1"/>
    <parent link="left_hip_pitch"/>
    <child link="left_knee"/>
    <limit effort="12.5" lower="-1.2392" upper="0.8727" velocity="8.5085"/>
  </joint>
  <joint name="shin_to_tarsus_left" type="continuous">
    <origin rpy="0 0 1.7976891" xyz="0.495436 0.067406 0"/>
    <axis xyz="0 0 1"/>
    <parent link="left_knee"/>
    <child link="left_tarsus"/>
    <limit effort="0" lower="-0.8779" upper="1.2497" velocity="20"/>
  </joint>
  <joint name="toe_pitch_joint_left" type="continuous">
    <origin rpy="0 0 1.1956" xyz="0.408 -0.04 0"/>
    <axis xyz="0 0 1"/>
    <parent link="left_tarsus"/>
    <child link="left_toe_pitch"/>
    <limit effort="0.9" lower="-0.785398163397" upper="0.785398163397" velocity="11.5"/>
  </joint>
  <joint name="toe_roll_joint_left" type="continuous">
    <origin rpy="0 1.57079632679 0" xyz="0 0 0"/>
    <axis xyz="0 0 1"/>
    <parent link="left_toe_pitch"/>
    <child link="left_toe_roll"/>
    <limit effort="0.9" lower="-0.6109" upper="0.6109" velocity="11.5"/>
  </joint>
  <transmission name="hip_abduction_trans_left" type="transmission_interface/SimpleTransmission">
    <joint name="hip_abduction_left"/>
    <actuator name="hip_abduction_motor_left"/>
    <motorInertia>2.7e-05</motorInertia>
    <mechanicalReduction>80</mechanicalReduction>
  </transmission>
  <transmission name="hip_rotation_trans_left" type="transmission_interface/SimpleTransmission">
    <joint name="hip_rotation_left"/>
    <actuator name="hip_rotation_motor_left"/>
    <motorInertia>2.7e-05</motorInertia>
    <mechanicalReduction>50</mechanicalReduction>
  </transmission>
  <transmission name="hip_flexion_trans_left" type="transmission_interface/SimpleTransmission">
    <joint name="hip_flexion_left"/>
    <actuator name="hip_flexion_motor_left"/>
    <motorInertia>4.71e-04</motorInertia>
    <mechanicalReduction>16</mechanicalReduction>
  </transmission>
  <transmission name="knee_joint_trans_left" type="transmission_interface/SimpleTransmission">
    <joint name="knee_joint_left"/>
    <actuator name="knee_joint_motor_left"/>
    <motorInertia>4.71e-04</motorInertia>
    <mechanicalReduction>16</mechanicalReduction>
  </transmission>
  <transmission name="toe_pitch_joint_trans_left" type="transmission_interface/SimpleTransmission">
    <joint name="toe_pitch_joint_left"/>
    <actuator name="toe_pitch_joint_motor_left"/>
    <motorInertia>1.4e-05</motorInertia>
    <mechanicalReduction>50</mechanicalReduction>
  </transmission>
  <transmission name="toe_roll_joint_trans_left" type="transmission_interface/SimpleTransmission">
    <joint name="toe_roll_joint_left"/>
    <actuator name="toe_roll_joint_motor_left"/>
    <motorInertia>1.4e-05</motorInertia>
    <mechanicalReduction>50</mechanicalReduction>
  </transmission>
  <transmission name="hip_abduction_trans_right" type="transmission_interface/SimpleTransmission">
    <joint name="hip_abduction_right"/>
    <actuator name="hip_abduction_motor_right"/>
    <motorInertia>2.7e-05</motorInertia>
    <mechanicalReduction>80</mechanicalReduction>
  </transmission>
  <transmission name="hip_rotation_trans_right" type="transmission_interface/SimpleTransmission">
    <joint name="hip_rotation_right"/>
    <actuator name="hip_rotation_motor_right"/>
    <motorInertia>2.7e-05</motorInertia>
    <mechanicalReduction>50</mechanicalReduction>
  </transmission>
  <transmission name="hip_flexion_trans_right" type="transmission_interface/SimpleTransmission">
    <joint name="hip_flexion_right"/>
    <actuator name="hip_flexion_motor_right"/>
    <motorInertia>4.71e-04</motorInertia>
    <mechanicalReduction>16</mechanicalReduction>
  </transmission>
  <transmission name="knee_joint_trans_right" type="transmission_interface/SimpleTransmission">
    <joint name="knee_joint_right"/>
    <actuator name="knee_joint_motor_right"/>
    <motorInertia>4.71e-04</motorInertia>
    <mechanicalReduction>16</mechanicalReduction>
  </transmission>
  <transmission name="toe_pitch_joint_trans_right" type="transmission_interface/SimpleTransmission">
    <joint name="toe_pitch_joint_right"/>
    <actuator name="toe_pitch_joint_motor_right"/>
    <motorInertia>1.4e-05</motorInertia>
    <mechanicalReduction>50</mechanicalReduction>
  </transmission>
  <transmission name="toe_roll_joint_trans_right" type="transmission_interface/SimpleTransmission">
    <joint name="toe_roll_joint_right"/>
    <actuator name="toe_roll_joint_motor_right"/>
    <motorInertia>1.4e-05</motorInertia>
    <mechanicalReduction>50</mechanicalReduction>
  </transmission>
</robot>
